Workbook
Name Segment_Puits: #N/A
Name Segment_Puits2: #N/A

Sheet Puits
A1: Puits | B1: Réservoir | C1: Zone | D1: Boosting | E1: Module | F1: Collecteur
A2: DJB001B | B2: Trias | C2: DJB | D2: SBS | E2: MPP2 | F2: DJB
A3: DJB002 | B3: Trias | C3: DJB | D3: SBS | E3: MPP2 | F3: DJB
A4: DJBW001B | B4: Trias | C4: DJB | D4: SBS | E4: MPP2 | F4: DJB
A5: HR006B | B5: Trias | C5: Sud | D5: SBS | E5: MPP2 | F5: S1
A6: HR007 | B6: Trias | C6: Centre | D6: SBC | E6: MPP4 | F6: E3
A7: HR010 | B7: Trias | C7: Centre | D7: SBC | E7: MPP0 | F7: E5
A8: HR011 | B8: Trias | C8: Centre | D8: SBC | E8: MPP0 | F8: E4
A9: HR012 | B9: Trias | C9: Sud | D9: SBS | E9: MPP2 | F9: S3
A10: HR015 | B10: Trias | C10: Centre | D10: SBC | E10: MPP0 | F10: W7
A11: HR016 | B11: Trias | C11: Centre | D11: SBC | E11: MPP0 | F11: E4
A12: HR017 | B12: Trias | C12: Centre | D12: SBC | E12: MPP0 | F12: W7
... A267: HRS031 | B267: Trias | C267: HRSud | D267: CTGS | E267: CTGS | F267: SS2

Sheet Test_SCADA (C&n)
A28: N° | B28: Puits | C28: Date | D28: Côte de mesure | E28: Qg (Msm3/j) | F28: WHP (bar) | G28: BHT (C°) | H28: BHP (bar) | I28: FGS | J28: S/C | K28: Zone
A29: 1 | B29: HRD001 | C29: 45280 | D29: 2115 | E29: 314 | F29: 36.4 | G29: 78.9 | H29: 56.367762 | I29: non | J29: TRSSSV | K29: =VLOOKUP(SCADA[[#This Row],[Puits]],Puits!$A$1:$F$267,3,FALSE) -> Sud
A30: 1 | B30: HRD001 | C30: 45280 | D30: 2115 | E30: 221 | F30: 37.6 | G30: 79 | H30: 56.701183 | I30: non | J30: TRSSSV | K30: =VLOOKUP(SCADA[[#This Row],[Puits]],Puits!$A$1:$F$267,3,FALSE) -> Sud
A31: 1 | B31: HRD001 | C31: 45280 | D31: 2115 | E31: 193 | F31: 42.8 | G31: 79.1 | H31: 58.191771 | I31: non | J31: TRSSSV | K31: =VLOOKUP(SCADA[[#This Row],[Puits]],Puits!$A$1:$F$267,3,FALSE) -> Sud
A32: 2 | B32: HR108 | C32: 45280 | D32: 2220 | E32: 339 | F32: 39.9 | G32: 82.43 | H32: 52.611872 | I32: non | J32: Déséquipé | K32: =VLOOKUP(SCADA[[#This Row],[Puits]],Puits!$A$1:$F$267,3,FALSE) -> Nord
A33: 2 | B33: HR108 | C33: 45280 | D33: 2220 | E33: 264 | F33: 47.3 | G33: 83.6 | H33: 60.055006 | I33: non | J33: Déséquipé | K33: =VLOOKUP(SCADA[[#This Row],[Puits]],Puits!$A$1:$F$267,3,FALSE) -> Nord
A34: 2 | B34: HR108 | C34: 45280 | D34: 2220 | E34: 137 | F34: 56.5 | G34: 84.75 | H34: 70.234153 | I34: non | J34: Déséquipé | K34: =VLOOKUP(SCADA[[#This Row],[Puits]],Puits!$A$1:$F$267,3,FALSE) -> Nord
A35: 3 | B35: HR109 | C35: 45281 | D35: 2190 | E35: 926 | F35: 41.8 | G35: 86.18 | H35: 56.652151 | I35: non | J35: Déséquipé | K35: =VLOOKUP(SCADA[[#This Row],[Puits]],Puits!$A$1:$F$267,3,FALSE) -> Nord
A36: 3 | B36: HR109 | C36: 45281 | D36: 2190 | E36: 698 | F36: 49.2 | G36: 87.16 | H36: 61.888821 | I36: non | J36: Déséquipé | K36: =VLOOKUP(SCADA[[#This Row],[Puits]],Puits!$A$1:$F$267,3,FALSE) -> Nord
A37: 3 | B37: HR109 | C37: 45281 | D37: 2190 | E37: 279 | F37: 59.7 | G37: 88.28 | H37: 70.665639 | I37: non | J37: Déséquipé | K37: =VLOOKUP(SCADA[[#This Row],[Puits]],Puits!$A$1:$F$267,3,FALSE) -> Nord
A38: 4 | B38: HRD006 | C38: 45281 | D38: 2040 | E38: 384 | F38: 34.8 | G38: 80.6 | H38: 56.612924 | I38: non | J38: équipé | K38: =VLOOKUP(SCADA[[#This Row],[Puits]],Puits!$A$1:$F$267,3,FALSE) -> Sud
A39: 4 | B39: HRD006 | C39: 45281 | D39: 2040 | E39: 316 | F39: 40.8 | G39: 81.2 | H39: 58.466353 | I39: non | J39: équipé | K39: =VLOOKUP(SCADA[[#This Row],[Puits]],Puits!$A$1:$F$267,3,FALSE) -> Sud
A40: 4 | B40: HRD006 | C40: 45281 | D40: 2040 | E40: 250 | F40: 47.9 | G40: 81.6 | H40: 61.251399 | I40: non | J40: équipé | K40: =VLOOKUP(SCADA[[#This Row],[Puits]],Puits!$A$1:$F$267,3,FALSE) -> Sud
... A98: 24 | B98: HRD013 | C98: 45292 | D98: 2140 | E98: 675 | F98: 41.5 | G98: 79.6 | H98: 52.593064 | I98: non | J98: Déséquipé | K98: =VLOOKUP(SCADA[[#This Row],[Puits]],Puits!$A$1:$F$267,3,FALSE) -> Sud
A99: 24 | B99: HRD013 | C99: 45292 | D99: 2140 | E99: 548 | F99: =+G99-12 -> 68.5 | G99: 80.5 | H99: 55.574286 | I99: non | J99: Déséquipé | K99: =VLOOKUP(SCADA[[#This Row],[Puits]],Puits!$A$1:$F$267,3,FALSE) -> Sud
A100: 24 | B100: HRD013 | C100: 45292 | D100: 2140 | E100: 448 | F100: =+G100-11.5 -> 69.5 | G100: 81 | H100: 57.810202 | I100: non | J100: Déséquipé | K100: =VLOOKUP(SCADA[[#This Row],[Puits]],Puits!$A$1:$F$267,3,FALSE) -> Sud
A101: 25 | B101: HR081 | C101: 45292 | D101: 1980 | E101: 449 | F101: 34.9 | G101: 85 | H101: 51.837952 | I101: non | J101: équipé | K101: =VLOOKUP(SCADA[[#This Row],[Puits]],Puits!$A$1:$F$267,3,FALSE) -> Nord
A102: 25 | B102: HR081 | C102: 45292 | D102: 1980 | E102: 371 | F102: 43.8 | G102: 86 | H102: 57.486582 | I102: non | J102: équipé | K102: =VLOOKUP(SCADA[[#This Row],[Puits]],Puits!$A$1:$F$267,3,FALSE) -> Nord
A103: 25 | B103: HR081 | C103: 45292 | D103: 1980 | E103: 270 | F103: 52.6 | G103: 87 | H103: 63.880518 | I103: non | J103: équipé | K103: =VLOOKUP(SCADA[[#This Row],[Puits]],Puits!$A$1:$F$267,3,FALSE) -> Nord
A104: 26 | B104: HR142 | C104: 45293 | D104: 2180 | E104: 850 | F104: 43.1 | G104: 84.7 | H104: 61.517115 | I104: non | J104: Déséquipé | K104: =VLOOKUP(SCADA[[#This Row],[Puits]],Puits!$A$1:$F$267,3,FALSE) -> Sud
A105: 26 | B105: HR142 | C105: 45293 | D105: 2180 | E105: 770 | F105: 47.6 | G105: 85.6 | H105: 64.54737 | I105: non | J105: Déséquipé | K105: =VLOOKUP(SCADA[[#This Row],[Puits]],Puits!$A$1:$F$267,3,FALSE) -> Sud
A106: 26 | B106: HR142 | C106: 45293 | D106: 2180 | E106: 670 | F106: 54 | G106: 86.3 | H106: 66.8029 | I106: non | J106: Déséquipé | K106: =VLOOKUP(SCADA[[#This Row],[Puits]],Puits!$A$1:$F$267,3,FALSE) -> Sud
A107: 27 | B107: HR125 | C107: 45294 | D107: 2200 | E107: 637 | F107: 36.4 | G107: 89.5 | H107: 62.487974 | I107: non | J107: Déséquipé | K107: =VLOOKUP(SCADA[[#This Row],[Puits]],Puits!$A$1:$F$267,3,FALSE) -> Nord
A108: 27 | B108: HR125 | C108: 45294 | D108: 2200 | E108: 475 | F108: 53.8 | G108: 91.8 | H108: 71.441445 | I108: non | J108: Déséquipé | K108: =VLOOKUP(SCADA[[#This Row],[Puits]],Puits!$A$1:$F$267,3,FALSE) -> Nord
A109: 27 | B109: HR125 | C109: 45294 | D109: 2200 | E109: 330 | F109: 63 | G109: 93.2 | H109: 77.698088 | I109: non | J109: Déséquipé | K109: =VLOOKUP(SCADA[[#This Row],[Puits]],Puits!$A$1:$F$267,3,FALSE) -> Nord
A110: 28 | B110: HR006B | C110: 45295 | D110: 2165 | E110: 621 | F110: 36 | G110: 85 | H110: 66.734253 | I110: non | J110: Déséquipé | K110: =VLOOKUP(SCADA[[#This Row],[Puits]],Puits!$A$1:$F$267,3,FALSE) -> Sud
A111: 28 | B111: HR006B | C111: 45295 | D111: 2165 | E111: 530 | F111: 45.4 | G111: 85.7 | H111: 68.921136 | I111: non | J111: Déséquipé | K111: =VLOOKUP(SCADA[[#This Row],[Puits]],Puits!$A$1:$F$267,3,FALSE) -> Sud
A112: 28 | B112: HR006B | C112: 45295 | D112: 2165 | E112: 319 | F112: 58.8 | G112: 86.7 | H112: 72.843796 | I112: non | J112: Déséquipé | K112: =VLOOKUP(SCADA[[#This Row],[Puits]],Puits!$A$1:$F$267,3,FALSE) -> Sud
... A265: 79 | B265: HR075 | C265: 45496 | D265: 2160 | E265: 838 | F265: 54.2 | G265: 85.031 | H265: 64.771005 | I265: non | J265: Déséquipé | K265: =VLOOKUP(SCADA[[#This Row],[Puits]],Puits!$A$1:$F$267,3,FALSE) -> Sud

Sheet Test_Séparateur (C&n)
A28: N° | B28: Puits | C28: Date | D28: Côte de mesure | E28: Qg (Msm3/j) | F28: Qc (sm3/j) | G28: Qw (sm3/j) | H28: WHP (bar) | I28: WHT (C°) | J28: BHT (C°) | K28: BHP (bar) | L28: FGS | M28: S/C | N28: Zone | O28: WGR | P28: CGR | Q28: do (g/cm3) | R28: dg (g/cm3) | S28: Salinité eau (g/l)
A29: 1 | B29: HR057 | C29: 45265 | D29: 2045 | E29: 153.229 | F29: 3.3 | G29: 0 | H29: 42.402757 | I29: 43.333333 | J29: 84 | K29: 50.997762 | L29: non | M29: équipé | N29: =VLOOKUP(Séparateur[[#This Row],[Puits]],Puits!$A$1:$F$267,3,FALSE) -> Centre | O29: =(Séparateur[[#This Row],[Qw (sm3/j)]]/(Séparateur[[#This Row],[Qg (Msm3/j)]]*1000))*1000000 -> 0 | P29: =(Séparateur[[#This Row],[Qc (sm3/j)]]/(Séparateur[[#This Row],[Qg (Msm3/j)]]*1000))*1000000 -> 21.536393 | Q29: 0.73 | R29: 0.667 | S29: 0
A30: 1 | B30: HR057 | C30: 45265 | D30: 2045 | E30: 121.205 | F30: 1.6 | G30: 0 | H30: 48.883829 | I30: 47.777778 | J30: 85.6 | K30: 58.275178 | L30: non | M30: équipé | N30: =VLOOKUP(Séparateur[[#This Row],[Puits]],Puits!$A$1:$F$267,3,FALSE) -> Centre | O30: =(Séparateur[[#This Row],[Qw (sm3/j)]]/(Séparateur[[#This Row],[Qg (Msm3/j)]]*1000))*1000000 -> 0 | P30: =(Séparateur[[#This Row],[Qc (sm3/j)]]/(Séparateur[[#This Row],[Qg (Msm3/j)]]*1000))*1000000 -> 13.200776 | Q30: 0.74 | R30: 0.667 | S30: 0
A31: 1 | B31: HR057 | C31: 45265 | D31: 2045 | E31: 75.076 | F31: 1.1 | G31: 0 | H31: 53.98595 | I31: 46.666667 | J31: 85.1 | K31: 63.880616 | L31: oui | M31: équipé | N31: =VLOOKUP(Séparateur[[#This Row],[Puits]],Puits!$A$1:$F$267,3,FALSE) -> Centre | O31: =(Séparateur[[#This Row],[Qw (sm3/j)]]/(Séparateur[[#This Row],[Qg (Msm3/j)]]*1000))*1000000 -> 0 | P31: =(Séparateur[[#This Row],[Qc (sm3/j)]]/(Séparateur[[#This Row],[Qg (Msm3/j)]]*1000))*1000000 -> 14.651819 | Q31: 0.72 | R31: 0.667 | S31: 0
A32: 2 | B32: HR200 | C32: 45271 | D32: 2000 | E32: 237.636 | F32: 2.67 | G32: 46.08 | H32: 37.24 | J32: 78.2 | K32: 60.378079 | L32: oui | M32: Déséquipé | N32: =VLOOKUP(Séparateur[[#This Row],[Puits]],Puits!$A$1:$F$267,3,FALSE) -> Sud | O32: =(Séparateur[[#This Row],[Qw (sm3/j)]]/(Séparateur[[#This Row],[Qg (Msm3/j)]]*1000))*1000000 -> 193.91001 | P32: =(Séparateur[[#This Row],[Qc (sm3/j)]]/(Séparateur[[#This Row],[Qg (Msm3/j)]]*1000))*1000000 -> 11.235671 | Q32: 0.727 | R32: 0.67 | S32: 356
A33: 2 | B33: HR200 | C33: 45271 | D33: 2000 | E33: 200.03 | F33: 2.23 | G33: 40.8 | H33: 41.4 | J33: 78.6 | K33: 62.532001 | L33: non | M33: Déséquipé | N33: =VLOOKUP(Séparateur[[#This Row],[Puits]],Puits!$A$1:$F$267,3,FALSE) -> Sud | O33: =(Séparateur[[#This Row],[Qw (sm3/j)]]/(Séparateur[[#This Row],[Qg (Msm3/j)]]*1000))*1000000 -> 203.9694 | P33: =(Séparateur[[#This Row],[Qc (sm3/j)]]/(Séparateur[[#This Row],[Qg (Msm3/j)]]*1000))*1000000 -> 11.148328 | Q33: 0.729 | R33: 0.67 | S33: 351
A34: 2 | B34: HR200 | C34: 45271 | D34: 2000 | E34: 106.163 | F34: 1.13 | G34: 4.8 | H34: 46.9 | J34: 78.8 | K34: 66.152438 | L34: non | M34: Déséquipé | N34: =VLOOKUP(Séparateur[[#This Row],[Puits]],Puits!$A$1:$F$267,3,FALSE) -> Sud | O34: =(Séparateur[[#This Row],[Qw (sm3/j)]]/(Séparateur[[#This Row],[Qg (Msm3/j)]]*1000))*1000000 -> 45.213492 | P34: =(Séparateur[[#This Row],[Qc (sm3/j)]]/(Séparateur[[#This Row],[Qg (Msm3/j)]]*1000))*1000000 -> 10.64401 | Q34: 0.726 | R34: 0.67 | S34: 353
A35: 3 | B35: HR055 | C35: 45317 | D35: 2030 | E35: 411.413 | F35: 4.36 | G35: 0 | H35: 37.093794 | I35: 62.777778 | J35: 83.2 | K35: 45.941836 | L35: oui | M35: Déséquipé | N35: =VLOOKUP(Séparateur[[#This Row],[Puits]],Puits!$A$1:$F$267,3,FALSE) -> Centre | O35: =(Séparateur[[#This Row],[Qw (sm3/j)]]/(Séparateur[[#This Row],[Qg (Msm3/j)]]*1000))*1000000 -> 0 | P35: =(Séparateur[[#This Row],[Qc (sm3/j)]]/(Séparateur[[#This Row],[Qg (Msm3/j)]]*1000))*1000000 -> 10.597623 | Q35: 0.745 | R35: 0.67 | S35: -
A36: 3 | B36: HR055 | C36: 45318 | D36: 2030 | E36: 307.694 | F36: 3.63 | G36: 0 | H36: 46.677507 | I36: 55 | J36: 86 | K36: 55.802718 | L36: oui | M36: Déséquipé | N36: =VLOOKUP(Séparateur[[#This Row],[Puits]],Puits!$A$1:$F$267,3,FALSE) -> Centre | O36: =(Séparateur[[#This Row],[Qw (sm3/j)]]/(Séparateur[[#This Row],[Qg (Msm3/j)]]*1000))*1000000 -> 0 | P36: =(Séparateur[[#This Row],[Qc (sm3/j)]]/(Séparateur[[#This Row],[Qg (Msm3/j)]]*1000))*1000000 -> 11.797435 | Q36: 0.734 | R36: 0.67 | S36: 49.72
A37: 3 | B37: HR055 | C37: 45318 | D37: 2030 | E37: 204.89 | F37: 2.78 | G37: 0 | H37: 51.71068 | I37: 57.777778 | J37: 87.2 | K37: 61.051007 | L37: oui | M37: Déséquipé | N37: =VLOOKUP(Séparateur[[#This Row],[Puits]],Puits!$A$1:$F$267,3,FALSE) -> Centre | O37: =(Séparateur[[#This Row],[Qw (sm3/j)]]/(Séparateur[[#This Row],[Qg (Msm3/j)]]*1000))*1000000 -> 0 | P37: =(Séparateur[[#This Row],[Qc (sm3/j)]]/(Séparateur[[#This Row],[Qg (Msm3/j)]]*1000))*1000000 -> 13.568256 | Q37: 0.735 | R37: 0.67 | S37: -
A38: 4 | B38: HRC067 | C38: 45320 | D38: 1915 | E38: 921.484 | F38: 5.37 | G38: 0.96 | H38: 45.988031 | I38: 63.333333 | J38: 87.3 | K38: 58.447547 | L38: oui | M38: équipé | N38: =VLOOKUP(Séparateur[[#This Row],[Puits]],Puits!$A$1:$F$267,3,FALSE) -> Centre | O38: =(Séparateur[[#This Row],[Qw (sm3/j)]]/(Séparateur[[#This Row],[Qg (Msm3/j)]]*1000))*1000000 -> 1.0417978 | P38: =(Séparateur[[#This Row],[Qc (sm3/j)]]/(Séparateur[[#This Row],[Qg (Msm3/j)]]*1000))*1000000 -> 5.8275564 | Q38: 0.745 | R38: 0.67 | S38: 6.084
A39: 4 | B39: HRC067 | C39: 45321 | D39: 1915 | E39: 702.485 | F39: 4.31 | G39: 0 | H39: 49.98699 | I39: 60 | J39: 88 | K39: 61.117887 | L39: oui | M39: équipé | N39: =VLOOKUP(Séparateur[[#This Row],[Puits]],Puits!$A$1:$F$267,3,FALSE) -> Centre | O39: =(Séparateur[[#This Row],[Qw (sm3/j)]]/(Séparateur[[#This Row],[Qg (Msm3/j)]]*1000))*1000000 -> 0 | P39: =(Séparateur[[#This Row],[Qc (sm3/j)]]/(Séparateur[[#This Row],[Qg (Msm3/j)]]*1000))*1000000 -> 6.1353623 | Q39: 0.745 | R39: 0.67 | S39: 0
A40: 4 | B40: HRC067 | C40: 45321 | D40: 1915 | E40: 477.258 | F40: 3.22 | G40: 0 | H40: 53.572264 | I40: 62.777778 | J40: 88.4 | K40: 63.255261 | L40: oui | M40: équipé | N40: =VLOOKUP(Séparateur[[#This Row],[Puits]],Puits!$A$1:$F$267,3,FALSE) -> Centre | O40: =(Séparateur[[#This Row],[Qw (sm3/j)]]/(Séparateur[[#This Row],[Qg (Msm3/j)]]*1000))*1000000 -> 0 | P40: =(Séparateur[[#This Row],[Qc (sm3/j)]]/(Séparateur[[#This Row],[Qg (Msm3/j)]]*1000))*1000000 -> 6.7468749 | Q40: 0.742 | R40: 0.67 | S40: 0
A41: 5 | B41: HR116 | C41: 45322 | D41: 2173 | E41: 350.145 | F41: 5.38 | G41: 0 | H41: 38.610641 | I41: 60 | J41: 87.1 | K41: 56.09 | L41: oui | M41: Déséquipé | N41: =VLOOKUP(Séparateur[[#This Row],[Puits]],Puits!$A$1:$F$267,3,FALSE) -> Nord | O41: =(Séparateur[[#This Row],[Qw (sm3/j)]]/(Séparateur[[#This Row],[Qg (Msm3/j)]]*1000))*1000000 -> 0 | P41: =(Séparateur[[#This Row],[Qc (sm3/j)]]/(Séparateur[[#This Row],[Qg (Msm3/j)]]*1000))*1000000 -> 15.365063 | Q41: 0.733 | R41: 0.67 | S41: 0
A42: 5 | B42: HR116 | C42: 45323 | D42: 2173 | E42: 235.357 | F42: 4.31 | G42: 0 | H42: 44.815922 | I42: 62.222222 | J42: 88.3 | K42: 58.35 | L42: oui | M42: Déséquipé | N42: =VLOOKUP(Séparateur[[#This Row],[Puits]],Puits!$A$1:$F$267,3,FALSE) -> Nord | O42: =(Séparateur[[#This Row],[Qw (sm3/j)]]/(Séparateur[[#This Row],[Qg (Msm3/j)]]*1000))*1000000 -> 0 | P42: =(Séparateur[[#This Row],[Qc (sm3/j)]]/(Séparateur[[#This Row],[Qg (Msm3/j)]]*1000))*1000000 -> 18.312606 | Q42: 0.733 | R42: 0.67 | S42: 0
A43: 5 | B43: HR116 | C43: 45323 | D43: 2173 | E43: 172.983 | F43: 2.89 | G43: 0 | H43: 50.331728 | I43: 62.777778 | J43: 88.7 | K43: 61.24 | L43: oui | M43: Déséquipé | N43: =VLOOKUP(Séparateur[[#This Row],[Puits]],Puits!$A$1:$F$267,3,FALSE) -> Nord | O43: =(Séparateur[[#This Row],[Qw (sm3/j)]]/(Séparateur[[#This Row],[Qg (Msm3/j)]]*1000))*1000000 -> 0 | P43: =(Séparateur[[#This Row],[Qc (sm3/j)]]/(Séparateur[[#This Row],[Qg (Msm3/j)]]*1000))*1000000 -> 16.706844 | Q43: 0.733 | R43: 0.67 | S43: 0
A44: 6 | B44: HR101 | C44: 45325 | D44: 2190 | E44: 691.489 | F44: 4.43 | G44: 0.52 | H44: 49.98699 | I44: 58.888889 | J44: 86.3 | K44: 63.139429 | L44: oui | M44: Déséquipé | N44: =VLOOKUP(Séparateur[[#This Row],[Puits]],Puits!$A$1:$F$267,3,FALSE) -> Nord | O44: =(Séparateur[[#This Row],[Qw (sm3/j)]]/(Séparateur[[#This Row],[Qg (Msm3/j)]]*1000))*1000000 -> 0.75200039 | P44: =(Séparateur[[#This Row],[Qc (sm3/j)]]/(Séparateur[[#This Row],[Qg (Msm3/j)]]*1000))*1000000 -> 6.4064649 | Q44: 0.781 | R44: 0.67 | S44: 5.616
A45: 6 | B45: HR101 | C45: 45325 | D45: 2190 | E45: 524.072 | F45: 2.96 | G45: 0.32 | H45: 55.847534 | I45: 56.666667 | J45: 87.3 | K45: 67.461063 | L45: oui | M45: Déséquipé | N45: =VLOOKUP(Séparateur[[#This Row],[Puits]],Puits!$A$1:$F$267,3,FALSE) -> Nord | O45: =(Séparateur[[#This Row],[Qw (sm3/j)]]/(Séparateur[[#This Row],[Qg (Msm3/j)]]*1000))*1000000 -> 0.61060312 | P45: =(Séparateur[[#This Row],[Qc (sm3/j)]]/(Séparateur[[#This Row],[Qg (Msm3/j)]]*1000))*1000000 -> 5.6480789 | Q45: 0.781 | R45: 0.67 | S45: 3.276
A46: 6 | B46: HR101 | C46: 45326 | D46: 2190 | E46: 363.453 | F46: 2.22 | G46: 0 | H46: 59.984388 | I46: 55.555556 | J46: 88.1 | K46: 71.781318 | L46: oui | M46: Déséquipé | N46: =VLOOKUP(Séparateur[[#This Row],[Puits]],Puits!$A$1:$F$267,3,FALSE) -> Nord | O46: =(Séparateur[[#This Row],[Qw (sm3/j)]]/(Séparateur[[#This Row],[Qg (Msm3/j)]]*1000))*1000000 -> 0 | P46: =(Séparateur[[#This Row],[Qc (sm3/j)]]/(Séparateur[[#This Row],[Qg (Msm3/j)]]*1000))*1000000 -> 6.10808 | Q46: 0.77 | R46: 0.67 | S46: 0
A47: 7 | B47: HR114 | C47: 45327 | D47: 2170 | E47: 541.869 | F47: 8.64 | G47: 1.12 | H47: 44.815922 | I47: 58.888889 | J47: 89.51 | K47: 69.705996 | L47: oui | M47: Déséquipé | N47: =VLOOKUP(Séparateur[[#This Row],[Puits]],Puits!$A$1:$F$267,3,FALSE) -> Nord | O47: =(Séparateur[[#This Row],[Qw (sm3/j)]]/(Séparateur[[#This Row],[Qg (Msm3/j)]]*1000))*1000000 -> 2.0669202 | P47: =(Séparateur[[#This Row],[Qc (sm3/j)]]/(Séparateur[[#This Row],[Qg (Msm3/j)]]*1000))*1000000 -> 15.944813 | Q47: 0.729 | R47: 0.67 | S47: 140
A48: 7 | B48: HR114 | C48: 45328 | D48: 2170 | E48: 378.301 | F48: 5.53 | G48: 0.72 | H48: 56.950695 | I48: 58.888889 | J48: 91.3 | K48: 76.738649 | L48: oui | M48: Déséquipé | N48: =VLOOKUP(Séparateur[[#This Row],[Puits]],Puits!$A$1:$F$267,3,FALSE) -> Nord | O48: =(Séparateur[[#This Row],[Qw (sm3/j)]]/(Séparateur[[#This Row],[Qg (Msm3/j)]]*1000))*1000000 -> 1.9032464 | P48: =(Séparateur[[#This Row],[Qc (sm3/j)]]/(Séparateur[[#This Row],[Qg (Msm3/j)]]*1000))*1000000 -> 14.617989 | Q48: 0.724 | R48: 0.67 | S48: 0
A49: 7 | B49: HR114 | C49: 45328 | D49: 2170 | E49: 248.679 | F49: 2.95 | G49: 0.31 | H49: 65.155456 | I49: 58.888889 | J49: 92.1 | K49: 80.323922 | L49: oui | M49: Déséquipé | N49: =VLOOKUP(Séparateur[[#This Row],[Puits]],Puits!$A$1:$F$267,3,FALSE) -> Nord | O49: =(Séparateur[[#This Row],[Qw (sm3/j)]]/(Séparateur[[#This Row],[Qg (Msm3/j)]]*1000))*1000000 -> 1.246587 | P49: =(Séparateur[[#This Row],[Qc (sm3/j)]]/(Séparateur[[#This Row],[Qg (Msm3/j)]]*1000))*1000000 -> 11.862682 | Q49: 0.724 | R49: 0.67 | S49: 117
... A91: 21 | B91: HR016 | C91: 45347 | D91: 2130 | E91: 527.42 | F91: 6.24 | G91: 0.48 | H91: 54.192792 | I91: 63.333333 | J91: 90.6 | K91: 65.106504 | L91: oui | M91: Déséquipé | N91: =VLOOKUP(Séparateur[[#This Row],[Puits]],Puits!$A$1:$F$267,3,FALSE) -> Centre | O91: =(Séparateur[[#This Row],[Qw (sm3/j)]]/(Séparateur[[#This Row],[Qg (Msm3/j)]]*1000))*1000000 -> 0.91009063 | P91: =(Séparateur[[#This Row],[Qc (sm3/j)]]/(Séparateur[[#This Row],[Qg (Msm3/j)]]*1000))*1000000 -> 11.831178 | Q91: 0.745 | R91: 0.668 | S91: 0
A92: 22 | B92: HRC069 | C92: 45349 | D92: 2120 | E92: 754.624 | F92: 3.44 | G92: 1.44 | H92: 40.748016 | J92: 88.5234 | K92: 68.086004 | L92: oui | M92: TRSSSV | N92: =VLOOKUP(Séparateur[[#This Row],[Puits]],Puits!$A$1:$F$267,3,FALSE) -> Centre | O92: =(Séparateur[[#This Row],[Qw (sm3/j)]]/(Séparateur[[#This Row],[Qg (Msm3/j)]]*1000))*1000000 -> 1.9082351 | P92: =(Séparateur[[#This Row],[Qc (sm3/j)]]/(Séparateur[[#This Row],[Qg (Msm3/j)]]*1000))*1000000 -> 4.5585616 | Q92: 0.777 | R92: 0.682 | S92: 0
A93: 22 | B93: HRC069 | C93: 45349 | D93: 2120 | E93: 563.608 | F93: 3 | G93: 1.2 | H93: 49.849095 | J93: 88.8234 | K93: 69.027828 | L93: non | M93: TRSSSV | N93: =VLOOKUP(Séparateur[[#This Row],[Puits]],Puits!$A$1:$F$267,3,FALSE) -> Centre | O93: =(Séparateur[[#This Row],[Qw (sm3/j)]]/(Séparateur[[#This Row],[Qg (Msm3/j)]]*1000))*1000000 -> 2.1291394 | P93: =(Séparateur[[#This Row],[Qc (sm3/j)]]/(Séparateur[[#This Row],[Qg (Msm3/j)]]*1000))*1000000 -> 5.3228485 | Q93: 0.77 | R93: 0.682 | S93: 0
A94: 22 | B94: HRC069 | C94: 45349 | D94: 2120 | E94: 372.079 | F94: 2.16 | G94: 0.36 | H94: 55.985429 | J94: 88.9234 | K94: 69.78763 | L94: oui | M94: TRSSSV | N94: =VLOOKUP(Séparateur[[#This Row],[Puits]],Puits!$A$1:$F$267,3,FALSE) -> Centre | O94: =(Séparateur[[#This Row],[Qw (sm3/j)]]/(Séparateur[[#This Row],[Qg (Msm3/j)]]*1000))*1000000 -> 0.96753646 | P94: =(Séparateur[[#This Row],[Qc (sm3/j)]]/(Séparateur[[#This Row],[Qg (Msm3/j)]]*1000))*1000000 -> 5.8052188 | Q94: 0.771 | R94: 0.684 | S94: 0
A95: 23 | B95: HR095 | C95: 45349 | D95: 2050 | E95: 466.039 | F95: 7.75 | G95: 0.52 | H95: 40.816963 | I95: 59.444444 | J95: 84.978 | K95: 51.105527 | L95: oui | M95: équipé | N95: =VLOOKUP(Séparateur[[#This Row],[Puits]],Puits!$A$1:$F$267,3,FALSE) -> Centre | O95: =(Séparateur[[#This Row],[Qw (sm3/j)]]/(Séparateur[[#This Row],[Qg (Msm3/j)]]*1000))*1000000 -> 1.1157864 | P95: =(Séparateur[[#This Row],[Qc (sm3/j)]]/(Séparateur[[#This Row],[Qg (Msm3/j)]]*1000))*1000000 -> 16.62951 | Q95: 0.744 | R95: 0.67 | S95: 0
A96: 23 | B96: HR095 | C96: 45349 | D96: 2050 | E96: 362.422 | F96: 4.77 | G96: 0.4 | H96: 47.573825 | I96: 55 | J96: 86.572 | K96: 57.352384 | L96: oui | M96: équipé | N96: =VLOOKUP(Séparateur[[#This Row],[Puits]],Puits!$A$1:$F$267,3,FALSE) -> Centre | O96: =(Séparateur[[#This Row],[Qw (sm3/j)]]/(Séparateur[[#This Row],[Qg (Msm3/j)]]*1000))*1000000 -> 1.1036858 | P96: =(Séparateur[[#This Row],[Qc (sm3/j)]]/(Séparateur[[#This Row],[Qg (Msm3/j)]]*1000))*1000000 -> 13.161453 | Q96: 0.739 | R96: 0.67 | S96: 0
A97: 23 | B97: HR095 | C97: 44985 | D97: 2050 | E97: 235.523 | F97: 1.488 | G97: 0.2 | H97: 53.917002 | I97: 50 | J97: 87.517 | K97: 63.774505 | L97: oui | M97: équipé | N97: =VLOOKUP(Séparateur[[#This Row],[Puits]],Puits!$A$1:$F$267,3,FALSE) -> Centre | O97: =(Séparateur[[#This Row],[Qw (sm3/j)]]/(Séparateur[[#This Row],[Qg (Msm3/j)]]*1000))*1000000 -> 0.84917397 | P97: =(Séparateur[[#This Row],[Qc (sm3/j)]]/(Séparateur[[#This Row],[Qg (Msm3/j)]]*1000))*1000000 -> 6.3178543 | Q97: 0.722 | R97: 0.67 | S97: 0
A98: 24 | B98: HRC011 | C98: 45350 | D98: 2135 | E98: 822.378 | F98: 10 | G98: 0.08 | H98: 48.056458 | I98: 57.777778 | J98: 87.826 | K98: 60.678553 | L98: oui | M98: Déséquipé | N98: =VLOOKUP(Séparateur[[#This Row],[Puits]],Puits!$A$1:$F$267,3,FALSE) -> Centre | O98: =(Séparateur[[#This Row],[Qw (sm3/j)]]/(Séparateur[[#This Row],[Qg (Msm3/j)]]*1000))*1000000 -> 0.097278867 | P98: =(Séparateur[[#This Row],[Qc (sm3/j)]]/(Séparateur[[#This Row],[Qg (Msm3/j)]]*1000))*1000000 -> 12.159858 | Q98: 0.761 | R98: 0.696 | S98: 0
A99: 24 | B99: HRC011 | C99: 45350 | D99: 2135 | E99: 626.685 | F99: 7.36 | G99: 0.087 | H99: 52.744893 | I99: 58.888889 | J99: 88.693 | K99: 64.21639 | L99: oui | M99: Déséquipé | N99: =VLOOKUP(Séparateur[[#This Row],[Puits]],Puits!$A$1:$F$267,3,FALSE) -> Centre | O99: =(Séparateur[[#This Row],[Qw (sm3/j)]]/(Séparateur[[#This Row],[Qg (Msm3/j)]]*1000))*1000000 -> 0.13882573 | P99: =(Séparateur[[#This Row],[Qc (sm3/j)]]/(Séparateur[[#This Row],[Qg (Msm3/j)]]*1000))*1000000 -> 11.744337 | Q99: 0.755 | R99: 0.698 | S99: 0
A100: 24 | B100: HRC011 | C100: 45351 | D100: 2135 | E100: 482.422 | F100: 6.4 | G100: 0.069 | H100: 55.916482 | J100: 89.114 | K100: 66.600115 | L100: oui | M100: Déséquipé | N100: =VLOOKUP(Séparateur[[#This Row],[Puits]],Puits!$A$1:$F$267,3,FALSE) -> Centre | O100: =(Séparateur[[#This Row],[Qw (sm3/j)]]/(Séparateur[[#This Row],[Qg (Msm3/j)]]*1000))*1000000 -> 0.1430283 | P100: =(Séparateur[[#This Row],[Qc (sm3/j)]]/(Séparateur[[#This Row],[Qg (Msm3/j)]]*1000))*1000000 -> 13.266393 | Q100: 0.749 | R100: 0.7 | S100: 0
A101: 25 | B101: HR029 | C101: 45351 | D101: 2035 | E101: 345.447 | F101: 6.29 | G101: 0.48 | H101: 38.265903 | I101: 56.111111 | J101: 86.057 | K101: 46.729493 | L101: oui | M101: équipé | N101: =VLOOKUP(Séparateur[[#This Row],[Puits]],Puits!$A$1:$F$267,3,FALSE) -> Centre | O101: =(Séparateur[[#This Row],[Qw (sm3/j)]]/(Séparateur[[#This Row],[Qg (Msm3/j)]]*1000))*1000000 -> 1.389504 | P101: =(Séparateur[[#This Row],[Qc (sm3/j)]]/(Séparateur[[#This Row],[Qg (Msm3/j)]]*1000))*1000000 -> 18.208292 | Q101: 0.736 | R101: 0.67 | S101: 0.702
A102: 25 | B102: HR029 | C102: 45351 | D102: 2035 | E102: 281.753 | F102: 4.77 | G102: 0.4 | H102: 43.436971 | I102: 55.555556 | J102: 87.35 | K102: 51.805207 | L102: oui | M102: équipé | N102: =VLOOKUP(Séparateur[[#This Row],[Puits]],Puits!$A$1:$F$267,3,FALSE) -> Centre | O102: =(Séparateur[[#This Row],[Qw (sm3/j)]]/(Séparateur[[#This Row],[Qg (Msm3/j)]]*1000))*1000000 -> 1.4196832 | P102: =(Séparateur[[#This Row],[Qc (sm3/j)]]/(Séparateur[[#This Row],[Qg (Msm3/j)]]*1000))*1000000 -> 16.929722 | Q102: 0.73 | R102: 0.67 | S102: 1.229
A103: 25 | B103: HR029 | C103: 45352 | D103: 2035 | E103: 199.748 | F103: 2.604 | G103: 0.08 | H103: 48.401196 | I103: 50.555556 | J103: 88.405 | K103: 56.928839 | L103: oui | M103: équipé | N103: =VLOOKUP(Séparateur[[#This Row],[Puits]],Puits!$A$1:$F$267,3,FALSE) -> Centre | O103: =(Séparateur[[#This Row],[Qw (sm3/j)]]/(Séparateur[[#This Row],[Qg (Msm3/j)]]*1000))*1000000 -> 0.40050464 | P103: =(Séparateur[[#This Row],[Qc (sm3/j)]]/(Séparateur[[#This Row],[Qg (Msm3/j)]]*1000))*1000000 -> 13.036426 | Q103: 0.722 | R103: 0.67 | S103: 0.351
A104: 26 | B104: HR030 | C104: 45352 | D104: 2135 | E104: 793.232 | F104: 9.12 | G104: 0.62 | H104: 42.88539 | I104: 54.444444 | J104: 89.206 | K104: 54.941908 | L104: oui | M104: Déséquipé | N104: =VLOOKUP(Séparateur[[#This Row],[Puits]],Puits!$A$1:$F$267,3,FALSE) -> Centre | O104: =(Séparateur[[#This Row],[Qw (sm3/j)]]/(Séparateur[[#This Row],[Qg (Msm3/j)]]*1000))*1000000 -> 0.78161244 | P104: =(Séparateur[[#This Row],[Qc (sm3/j)]]/(Séparateur[[#This Row],[Qg (Msm3/j)]]*1000))*1000000 -> 11.497267 | Q104: 0.761 | R104: 0.69 | S104: 0.47
A105: 26 | B105: HR030 | C105: 45352 | D105: 2135 | E105: 617.428 | F105: 7.2 | G105: 0.48 | H105: 47.849616 | I105: 56.666667 | J105: 90.203 | K105: 58.672247 | L105: non | M105: Déséquipé | N105: =VLOOKUP(Séparateur[[#This Row],[Puits]],Puits!$A$1:$F$267,3,FALSE) -> Centre | O105: =(Séparateur[[#This Row],[Qw (sm3/j)]]/(Séparateur[[#This Row],[Qg (Msm3/j)]]*1000))*1000000 -> 0.77741858 | P105: =(Séparateur[[#This Row],[Qc (sm3/j)]]/(Séparateur[[#This Row],[Qg (Msm3/j)]]*1000))*1000000 -> 11.661279 | Q105: 0.755 | R105: 0.686 | S105: 0.41
A106: 26 | B106: HR030 | C106: 45352 | D106: 2135 | E106: 449.557 | F106: 5.52 | G106: 0.36 | H106: 51.503837 | I106: 56.111111 | J106: 90.915 | K106: 61.605966 | L106: oui | M106: Déséquipé | N106: =VLOOKUP(Séparateur[[#This Row],[Puits]],Puits!$A$1:$F$267,3,FALSE) -> Centre | O106: =(Séparateur[[#This Row],[Qw (sm3/j)]]/(Séparateur[[#This Row],[Qg (Msm3/j)]]*1000))*1000000 -> 0.80078833 | P106: =(Séparateur[[#This Row],[Qc (sm3/j)]]/(Séparateur[[#This Row],[Qg (Msm3/j)]]*1000))*1000000 -> 12.278754 | Q106: 0.748 | R106: 0.682 | S106: 1.053
A107: 27 | B107: HRC045 | C107: 45353 | D107: 2190 | E107: 855.006 | F107: 11.2 | G107: 1.04 | H107: 44.953818 | I107: 61.111111 | J107: 90.329 | K107: 57.959881 | L107: oui | M107: Déséquipé | N107: =VLOOKUP(Séparateur[[#This Row],[Puits]],Puits!$A$1:$F$267,3,FALSE) -> Centre | O107: =(Séparateur[[#This Row],[Qw (sm3/j)]]/(Séparateur[[#This Row],[Qg (Msm3/j)]]*1000))*1000000 -> 1.2163657 | P107: =(Séparateur[[#This Row],[Qc (sm3/j)]]/(Séparateur[[#This Row],[Qg (Msm3/j)]]*1000))*1000000 -> 13.099323 | Q107: 0.754 | R107: 0.678 | S107: 1
A108: 27 | B108: HRC045 | C108: 45353 | D108: 2190 | E108: 652.989 | F108: 8.8 | G108: 0.64 | H108: 48.332249 | I108: 63.333333 | J108: 90.85 | K108: 59.876899 | L108: oui | M108: Déséquipé | N108: =VLOOKUP(Séparateur[[#This Row],[Puits]],Puits!$A$1:$F$267,3,FALSE) -> Centre | O108: =(Séparateur[[#This Row],[Qw (sm3/j)]]/(Séparateur[[#This Row],[Qg (Msm3/j)]]*1000))*1000000 -> 0.98010839 | P108: =(Séparateur[[#This Row],[Qc (sm3/j)]]/(Séparateur[[#This Row],[Qg (Msm3/j)]]*1000))*1000000 -> 13.47649 | Q108: 0.74 | R108: 0.682 | S108: 0
...

Sheet FGS
A1: Test avec SCADA | H1: Test avec Séparateur Nord et Sud | Q1: Test avec Séparateur Centre
A2: Puits | B2: Date | C2: Qg (Msm3/j) | D2: Côte de mesure (m) | E2: BHP (psi) | F2: BHT (C°) | H2: Puits | I2: Date | J2: Qg (Msm3/j) | K2: Qc (sm3/j) | L2: Qw (sm3/j) | M2: Côte de mesure (m) | N2: BHP (psi) | O2: BHT (C°) | Q2: Puits | R2: Date | S2: Qg (Msm3/j) | T2: Qc (sm3/j) | U2: Qw (sm3/j) | V2: Côte de mesure (m) | W2: BHP (psi) | X2: BHT (C°)
A3: HRD025 | B3: 45321 | C3: 948 | D3: 0 | E3: 672.094 | F3: 17.313 | H3: HR114 | I3: 45327 | J3: 541.869 | K3: 8.64 | L3: 1.12 | M3: 0 | N3: 668.765 | O3: 26.996 | Q3: HR007 | R3: 45433 | S3: 687.262 | T3: 11.9 | U3: 0.69 | V3: 0 | W3: 619.184 | X3: 31.544
A4: HRD025 | B4: 45321 | C4: 948 | D4: 2025 | E4: 865.876 | F4: 76.757 | H4: HR114 | I4: 45327 | J4: 541.869 | K4: 8.64 | L4: 1.12 | M4: 2070 | N4: 995.771 | O4: 86.737 | Q4: HR007 | R4: 45433 | S4: 687.262 | T4: 11.9 | U4: 0.69 | V4: 500 | W4: 616.974 | X4: 63.444
A5: HRD025 | B5: 45321 | C5: 948 | D5: 2075 | E5: 870.382 | F5: 77.829 | H5: HR114 | I5: 45327 | J5: 541.869 | K5: 8.64 | L5: 1.12 | M5: 2120 | N5: 1005.984 | O5: 88.349 | Q5: HR007 | R5: 45433 | S5: 687.262 | T5: 11.9 | U5: 0.69 | V5: 1000 | W5: 812.555 | X5: 77.709
A6: HRD025 | B6: 45321 | C6: 948 | D6: 2126 | E6: 877.551 | F6: 78.761 | H6: HR114 | I6: 45327 | J6: 541.869 | K6: 8.64 | L6: 1.12 | M6: 2170 | N6: 1011.257 | O6: 89.51 | Q6: HR007 | R6: 45433 | S6: 687.262 | T6: 11.9 | U6: 0.69 | V6: 1500 | W6: 898.991 | X6: 82.998
A7: HRD024 | B7: 45322 | C7: 954 | D7: 0 | E7: 556.379 | F7: 15.764 | H7: HR114 | I7: 45327 | J7: 541.869 | K7: 8.64 | L7: 1.12 | M7: 2120 | N7: 1004.809 | O7: 89.362 | Q7: HR007 | R7: 45433 | S7: 687.262 | T7: 11.9 | U7: 0.69 | V7: 2000 | W7: 982.157 | X7: 87.17
A8: HRD024 | B8: 45322 | C8: 954 | D8: 2050 | E8: 744.549 | F8: 78.546 | H8: HR114 | I8: 45327 | J8: 541.869 | K8: 8.64 | L8: 1.12 | M8: 2070 | N8: 997.14 | O8: 89.071 | Q8: HR007 | R8: 45433 | S8: 687.262 | T8: 11.9 | U8: 0.69 | V8: 2115 | W8: 1000.448 | X8: 88.065
A9: HRD024 | B9: 45322 | C9: 954 | D9: 2100 | E9: 748.572 | F9: 79.978 | H9: HR114 | I9: 45327 | J9: 541.869 | K9: 8.64 | L9: 1.12 | M9: 0 | N9: 677.041 | O9: 68.393 | Q9: HR007 | R9: 45433 | S9: 687.262 | T9: 11.9 | U9: 0.69 | V9: 2165 | W9: 1004.453 | X9: 88.381 | Y9: =(W9-W8)*0.068948/(V9-V8) -> 0.0055227348
A10: HRD024 | B10: 45322 | C10: 954 | D10: 2157 | E10: 750.107 | F10: 80.727 | H10: HR114 | I10: 45328 | J10: 378.301 | K10: 5.53 | L10: 0.72 | M10: 0 | N10: 859.43 | O10: 11.9 | Q10: HR010 | R10: 45371 | S10: 601.288 | T10: 5.16 | U10: 0.6 | V10: 0 | W10: 532.715 | X10: 27.137
A11: HR084 | B11: 45323 | C11: 1264 | D11: 0 | E11: 581.652 | F11: 12.992 | H11: HR114 | I11: 45328 | J11: 378.301 | K11: 5.53 | L11: 0.72 | M11: 2070 | N11: 1100.33 | O11: 89.5 | Q11: HR010 | R11: 45371 | S11: 601.288 | T11: 5.16 | U11: 0.6 | V11: 1000 | W11: 596.431 | X11: 71.241
A12: HR084 | B12: 45323 | C12: 1264 | D12: 2080 | E12: 838.873 | F12: 79.692 | H12: HR114 | I12: 45328 | J12: 378.301 | K12: 5.53 | L12: 0.72 | M12: 2120 | N12: 1107.37 | O12: 90.8 | Q12: HR010 | R12: 45371 | S12: 601.288 | T12: 5.16 | U12: 0.6 | V12: 1500 | W12: 629.433 | X12: 77.702
A13: HR084 | B13: 45323 | C13: 1264 | D13: 2130 | E13: 846.466 | F13: 81.177 | H13: HR114 | I13: 45328 | J13: 378.301 | K13: 5.53 | L13: 0.72 | M13: 2170 | N13: 1132.68 | O13: 91.3 | Q13: HR010 | R13: 45371 | S13: 601.288 | T13: 5.16 | U13: 0.6 | V13: 2000 | W13: 661.408 | X13: 81.254
A14: HR084 | B14: 45323 | C14: 1264 | D14: 2182 | E14: 852.537 | F14: 82.345 | H14: HR114 | I14: 45328 | J14: 248.679 | K14: 2.95 | L14: 0.31 | M14: 2170 | N14: 1165.14 | O14: 92.1 | Q14: HR010 | R14: 45371 | S14: 601.288 | T14: 5.16 | U14: 0.6 | V14: 2080 | W14: 666.385 | X14: 82.637
A15: HR088 (2) | B15: 45324 | C15: 320 | D15: 0 | E15: 491.42 | F15: 10.7 | H15: HR114 | I15: 45328 | J15: 248.679 | K15: 2.95 | L15: 0.31 | M15: 2120 | N15: 1160.44 | O15: 91.8 | Q15: HR011 | R15: 06/07/204 | S15: 1146.6023 | T15: 10.2 | U15: 0.43 | V15: 0 | W15: 699.763 | X15: 40.802
A16: HR088 (2) | B16: 45324 | C16: 320 | D16: 1975 | E16: 658.6 | F16: 75.9 | H16: HR114 | I16: 45328 | J16: 248.679 | K16: 2.95 | L16: 0.31 | M16: 2070 | N16: 1155.2 | O16: 91.3 | Q16: HR011 | R16: 45479 | S16: 1146.6023 | T16: 10.2 | U16: 0.43 | V16: 500 | W16: 753.48 | X16: 66.306
A17: HR088 (2) | B17: 45324 | C17: 320 | D17: 2025 | E17: 661.72 | F17: 77.2 | H17: HR114 | I17: 45328 | J17: 248.679 | K17: 2.95 | L17: 0.31 | M17: 0 | N17: 955.2 | O17: 65.3 | Q17: HR011 | R17: 45479 | S17: 1146.6023 | T17: 10.2 | U17: 0.43 | V17: 1000 | W17: 810.968 | X17: 75.279
A18: HR088 (2) | B18: 45324 | C18: 320 | D18: 2075 | E18: 665.35 | F18: 77.5 | H18: HR101 | I18: 45325 | J18: 691.489 | K18: 4.43 | L18: 0.52 | M18: 0 | N18: 728.77 | O18: 22.7 | Q18: HR011 | R18: 45479 | S18: 1146.6023 | T18: 10.2 | U18: 0.43 | V18: 1500 | W18: 866.898 | X18: 81.394
A19: HR088 (2) | B19: 45324 | C19: 320 | D19: 2116 | E19: 666.74 | F19: 77.7 | H19: HR101 | I19: 45325 | J19: 691.489 | K19: 4.43 | L19: 0.52 | M19: 2050 | N19: 899.96 | O19: 85 | Q19: HR011 | R19: 45479 | S19: 1146.6023 | T19: 10.2 | U19: 0.43 | V19: 1750 | W19: 894.012 | X19: 84.538
A20: HR088 (2) | B20: 45324 | C20: 85 | D20: 2116 | E20: 822.47 | F20: 79.6 | H20: HR101 | I20: 45325 | J20: 691.489 | K20: 4.43 | L20: 0.52 | M20: 2100 | N20: 904.32 | O20: 85.6 | Q20: HR011 | R20: 45479 | S20: 1146.6023 | T20: 10.2 | U20: 0.43 | V20: 2000 | W20: 923.909 | X20: 87.357
A21: HR088 (2) | B21: 45324 | C21: 85 | D21: 2075 | E21: 819.9 | F21: 78.8 | H21: HR101 | I21: 45325 | J21: 691.489 | K21: 4.43 | L21: 0.52 | M21: 2140 | N21: 908.61 | O21: 86 | Q21: HR011 | R21: 45479 | S21: 1146.6023 | T21: 10.2 | U21: 0.43 | V21: 2050 | W21: 930.125 | X21: 88.649
A22: HR088 (2) | B22: 45324 | C22: 85 | D22: 2025 | E22: 816.83 | F22: 78.3 | H22: HR101 | I22: 45325 | J22: 691.489 | K22: 4.43 | L22: 0.52 | M22: 2190 | N22: 915.76 | O22: 86.3 | Q22: HR011 | R22: 45479 | S22: 1146.6023 | T22: 10.2 | U22: 0.43 | V22: 2100 | W22: 931.519 | X22: 90.741
A23: HR088 (2) | B23: 45324 | C23: 85 | D23: 1975 | E23: 813.84 | F23: 77.8 | H23: HR101 | I23: 45325 | J23: 524.072 | K23: 2.96 | L23: 0.32 | M23: 2190 | N23: 978.44 | O23: 87.3 | Q23: HR015 | R23: 45367 | S23: 832.537 | T23: 11.04 | U23: 0.78 | V23: 0 | W23: 596.523 | X23: 19.306
A24: HR088 (2) | B24: 45324 | C24: 85 | D24: 0 | E24: 696.11 | F24: 40.5 | H24: HR101 | I24: 45325 | J24: 524.072 | K24: 2.96 | L24: 0.32 | M24: 2140 | N24: 975.5 | O24: 87 | Q24: HR015 | R24: 45367 | S24: 832.537 | T24: 11.04 | U24: 0.78 | V24: 1000 | W24: 677.45 | X24: 58.099
A25: HR110 | B25: 45324 | C25: 251 | D25: 0 | E25: 509.759 | F25: 10.207 | H25: HR101 | I25: 45325 | J25: 524.072 | K25: 2.96 | L25: 0.32 | M25: 2100 | N25: 974.42 | O25: 86.8 | Q25: HR015 | R25: 45367 | S25: 832.537 | T25: 11.04 | U25: 0.78 | V25: 1970 | W25: 760.529 | X25: 77.039
A26: HR110 | B26: 45324 | C26: 251 | D26: 2050 | E26: 766.104 | F26: 82.637 | H26: HR101 | I26: 45325 | J26: 524.072 | K26: 2.96 | L26: 0.32 | M26: 2050 | N26: 972.46 | O26: 86.5 | Q26: HR015 | R26: 45367 | S26: 832.537 | T26: 11.04 | U26: 0.78 | V26: 2020 | W26: 766.954 | X26: 81.397
A27: HR110 | B27: 45324 | C27: 251 | D27: 2100 | E27: 771.079 | F27: 84.713 | H27: HR101 | I27: 45325 | J27: 524.072 | K27: 2.96 | L27: 0.32 | M27: 0 | N27: 827.13 | O27: 39.8 | Q27: HR015 | R27: 45367 | S27: 832.537 | T27: 11.04 | U27: 0.78 | V27: 2070 | W27: 771.158 | X27: 85.823
... A95: HR075 | B95: 45496 | C95: 1498 | D95: 2000 | E95: 825.691 | F95: 78.464 | H95: HR157 | I95: 45581 | J95: 252.624 | K95: 1.12 | L95: 0.05 | M95: 2120 | N95: 641.979 | O95: 79.905 | Q95: HR025 | R95: 45475 | S95: 280.68563 | T95: 6.1536 | U95: 0.4512 | V95: 0 | W95: 489 | X95: 35.64
A96: HR075 | B96: 45496 | C96: 1498 | D96: 2050 | E96: 832.237 | F96: 80.918 | Q96: HR025 | R96: 45475 | S96: 280.68563 | T96: 6.1536 | U96: 0.4512 | V96: 500 | W96: 535.461 | X96: 53.203
A97: HR075 | B97: 45496 | C97: 1498 | D97: 2100 | E97: 838.861 | F97: 82.092 | Q97: HR025 | R97: 45475 | S97: 280.68563 | T97: 6.1536 | U97: 0.4512 | V97: 1000 | W97: 579.322 | X97: 64.937
A98: HR075 | B98: 45496 | C98: 1498 | D98: 2160 | E98: 845.131 | F98: 83.436 | Q98: HR025 | R98: 45475 | S98: 280.68563 | T98: 6.1536 | U98: 0.4512 | V98: 1500 | W98: 617.458 | X98: 73.468
Q99: HR025 | R99: 45475 | S99: 280.68563 | T99: 6.1536 | U99: 0.4512 | V99: 2070 | W99: 659.428 | X99: 79.298
Q100: HR025 | R100: 45475 | S100: 280.68563 | T100: 6.1536 | U100: 0.4512 | V100: 2120 | W100: 662.888 | X100: 81.657
Q101: HR025 | R101: 45475 | S101: 280.68563 | T101: 6.1536 | U101: 0.4512 | V101: 2170 | W101: 667.856 | X101: 84.207
Q102: HR026 | R102: 45458 | S102: 703.02965 | T102: 2.832 | U102: 0.6144 | V102: 0 | W102: 575.041 | X102: 33.983
Q103: HR026 | R103: 45458 | S103: 703.02965 | T103: 2.832 | U103: 0.6144 | V103: 500 | W103: 612.805 | X103: 71.519
Q104: HR026 | R104: 45458 | S104: 703.02965 | T104: 2.832 | U104: 0.6144 | V104: 1000 | W104: 650.238 | X104: 77.764
Q105: HR026 | R105: 45458 | S105: 703.02965 | T105: 2.832 | U105: 0.6144 | V105: 1500 | W105: 686.557 | X105: 82.344
Q106: HR026 | R106: 45458 | S106: 703.02965 | T106: 2.832 | U106: 0.6144 | V106: 1980 | W106: 721.279 | X106: 85.415
Q107: HR026 | R107: 45458 | S107: 703.02965 | T107: 2.832 | U107: 0.6144 | V107: 2030 | W107: 726.41 | X107: 85.903
...
